<?xml version="1.0"?>
<robot name="hdt_7dof" xmlns:xacro="http://www.ros.org/wiki/xacro">

	<!-- constants -->
	<xacro:property name="PI" value="3.1415926535897931"/>

	<!-- materials -->
	<material name="titanium">
		<color rgba="${175/255} ${168/255} ${163/255} 1.0"/>
	</material>

	<material name="yellow">
		<color rgba="${255/255} ${189/255} ${13/255} 1.0"/>
	</material>

	<material name="green">
		<color rgba="${0/255} ${50/255} ${0/255} 1.0"/>
	</material>

	<!-- import gazebo definitions 
	<xacro:include filename="$(find hdt_mk3_m_description)/urdf/hdt_mk3_m.gazebo" /> -->

	<!-- segment 0 -->
	<link name="base_link">
		<!--<collision>
			<origin xyz="0 0 0" rpy="0 0 0"/>
			<geometry>
				<mesh filename="package://hdt_mk3_m_description/meshes/hdt_mk3_m_ik.STL"/>
			</geometry>
		</collision>-->

		<visual>
			<origin xyz="0 0 0" rpy="0 0 0"/>
			<geometry>
				<mesh filename="package://hdt_mk3_m_description/meshes/hdt_mk3_m_ik.STL"/>
			</geometry>
			<material name="green"/>
		</visual>

		<!--<inertial>
		<origin xyz="-0.04488 0 0" rpy="0 0 0"/>
		<mass value="1.00775"/>
			<inertia
			ixx="0.00064952" ixy="0.0" ixz="0.0"
			iyy="0.00104342" iyz="0.0"
			izz="0.00104342"/>
		</inertial>-->
	</link>

	<joint name="joint0" type="fixed">
		<origin xyz="0 0 -0.04695" rpy="0 0 0"/>
		<parent link="base_link"/>
		<child link="link0"/>
	</joint>

	<link name="link0">
		<!--<collision>
			<origin xyz="0 0 0" rpy="0 0 0"/>
			<geometry>
				<mesh filename="package://hdt_mk3_m_description/meshes/hdt_mk3_m_0.STL"/>
			</geometry>
		</collision>-->

		<visual>
			<origin xyz="0 0 0" rpy="0 0 0"/>
			<geometry>
				<mesh filename="package://hdt_mk3_m_description/meshes/hdt_mk3_m_0.STL"/>
			</geometry>
			<material name="titanium"/>
		</visual>

		<!--<inertial>
		<origin xyz="-0.04488 0 0" rpy="0 0 0"/>
		<mass value="1.00775"/>
			<inertia
			ixx="0.00064952" ixy="0.0" ixz="0.0"
			iyy="0.00104342" iyz="0.0"
			izz="0.00104342"/>
		</inertial>-->
	</link>

	<!-- segment 1 -->
	<joint name="joint1" type="revolute">
		<hdt id="1"/>
		<axis xyz="0 0 1"/>
		<limit effort="60.0" lower="-2.0944" upper="2.0944" velocity="2.0944"/>
		<origin xyz="0 0 -0.0002" rpy="0 0 0"/>
		<parent link="link0"/>
		<child link="link1"/>
    		<dynamics damping="0.7" friction="0.0"/>
	</joint>

	<transmission name="tran1">
		<type>transmission_interface/SimpleTransmission</type>
		<joint name="joint1">
			<hardwareInterface>EffortJointInterface</hardwareInterface>
		</joint>
		<actuator name="motor1">
			<mechanicalReduction>1</mechanicalReduction>
		</actuator>
	</transmission>

	<link name="link1">
		<!--<collision>
			<origin xyz="0 0 0" rpy="0 0 0"/>
			<geometry>
				<mesh filename="package://hdt_mk3_m_description/meshes/hdt_mk3_m_1.STL"/>
			</geometry>
		</collision>-->

		<visual>
			<origin xyz="0 0 0" rpy="0 0 0"/>
			<geometry>
				<mesh filename="package://hdt_mk3_m_description/meshes/hdt_mk3_m_1.STL"/>
			</geometry>
			<material name="yellow"/>
		</visual>

		<!--<inertial>
		<origin xyz="-0.04488 0 0" rpy="0 0 0"/>
		<mass value="1.00775"/>
			<inertia
			ixx="0.00064952" ixy="0.0" ixz="0.0"
			iyy="0.00104342" iyz="0.0"
			izz="0.00104342"/>
		</inertial>-->
	</link>

	<joint name="joint1f" type="fixed">
		<parent link="link1"/>
		<child link="link2a"/>
		<origin xyz="0 0 -0.08651" rpy="0 0 0"/>
	</joint>

	<link name="link2a">
		<!--<collision>
			<origin xyz="0 0 0" rpy="0 0 0"/>
			<geometry>
				<mesh filename="package://hdt_mk3_m_description/meshes/hdt_mk3_m_2a.STL"/>
			</geometry>
		</collision>-->

		<visual>
			<origin xyz="0 0 0" rpy="0 0 0"/>
			<geometry>
				<mesh filename="package://hdt_mk3_m_description/meshes/hdt_mk3_m_2a.STL"/>
			</geometry>
			<material name="titanium"/>
		</visual>

		<!--<inertial>
			<origin xyz="-0.04416876 0 0" rpy="0 0 0"/>
			<mass value="0.66774822"/>
			<inertia
			ixx="0.00062987" ixy="0.0" ixz="0.0"
			iyy="0.00091291" iyz="0.0"
			izz="0.00110241"/>
		</inertial>-->
	</link>

	<!-- segment 2 -->
	<joint name="joint2" type="revolute">
		<hdt id="2"/>
		<axis xyz="1 0 0"/>
		<limit effort="60.0" lower="-3.1416" upper="1.5708" velocity="2.0944"/>
		<origin xyz="0.0257 -0.0420 -0.0870" rpy="0 0 0"/>
		<parent link="link2a"/>
		<child link="link2b"/>
    		<dynamics damping="0.7" friction="0.0"/>
	</joint>

	<transmission name="tran2">
		<type>transmission_interface/SimpleTransmission</type>
		<joint name="joint2">
			<hardwareInterface>EffortJointInterface</hardwareInterface>
		</joint>
		<actuator name="motor2">
			<mechanicalReduction>1</mechanicalReduction>
		</actuator>
	</transmission>

	<link name="link2b">
		<!--<collision>
			<origin xyz="0 0 0" rpy="0 0 0"/>
			<geometry>
				<mesh filename="package://hdt_mk3_m_description/meshes/hdt_mk3_m_2b.STL"/>
			</geometry>
		</collision>-->

		<visual>
			<origin xyz="0 0 0.0" rpy="0 0 0"/>
			<geometry>
				<mesh filename="package://hdt_mk3_m_description/meshes/hdt_mk3_m_2b.STL"/>
			</geometry>
			<material name="titanium"/>
		</visual>

		<!--<inertial>
			<origin xyz="0 0 -0.02018105" rpy="0 0 0"/>
			<mass value="0.69896"/>
			<inertia
			ixx="0.00088116" ixy="0.0" ixz="0.0"
			iyy="0.00094182" iyz="0.0"
			izz="0.00032992"/>
		</inertial>-->
	</link>

	<!-- segment 3 -->
	<joint name="joint2f" type="fixed">
		<origin xyz="-0.02573 0.0420 -0.1070" rpy="0 0 0" />
		<parent link="link2b"/>
		<child link="link3"/>
	</joint>

	<link name="link3">
		<!--<collision>
			<origin xyz="0 0 0.0" rpy="0 0 0"/>
			<geometry>
				<mesh filename="package://hdt_mk3_m_description/meshes/hdt_mk3_m_3.STL"/>
			</geometry>
		</collision>-->

		<visual>
			<origin xyz="0 0 0.0" rpy="0 0 0"/>
			<geometry>
				<mesh filename="package://hdt_mk3_m_description/meshes/hdt_mk3_m_3.STL"/>
			</geometry>
			<material name="yellow"/>
		</visual>

		<!--<inertial>
			<origin xyz="0 0 -0.08013953" rpy="0 0 0"/>
			<mass value="1.77733729"/>
			<inertia
			ixx="0.00450640" ixy="0.0" ixz="0.0"
			iyy="0.00450640" iyz="0.0"
			izz="0.00114447"/>
		</inertial>-->
	</link>

	<joint name="joint3f" type="fixed">
		<origin xyz="0 0 -0.14311" rpy="0 0 0"/>
		<parent link="link3"/>
		<child link="link4a"/>
	</joint>

	<link name="link4a">
		<!--<collision>
			<origin xyz="0 0 0" rpy="0 0 0"/>
			<geometry>
				<mesh filename="package://hdt_mk3_m_description/meshes/hdt_mk3_m_4a.STL"/>
			</geometry>
		</collision>-->

		<visual>
			<origin xyz="0 0 0.0" rpy="0 0 0"/>
			<geometry>
				<mesh filename="package://hdt_mk3_m_description/meshes/hdt_mk3_m_4a.STL"/>
			</geometry>
			<material name="titanium"/>
		</visual>

		<!--<inertial>
			<origin xyz="0 0 -0.04416876" rpy="0 0 0"/>
			<mass value="0.66774822"/>
			<inertia
			ixx="0.00091291" ixy="0.0" ixz="0.0"
			iyy="0.00110241" iyz="0.0"
			izz="0.00062987"/>
		</inertial>-->
	</link>

	<!-- segment 4 -->
	<joint name="joint4" type="revolute">
		<hdt id="4"/>
		<axis xyz="1 0 0"/>
		<limit effort="60.0" lower="-1.5708" upper="3.1416" velocity="2.0944"/>
		<origin xyz="0.0257 -0.0420 -0.0870" rpy="0 0 0"/>
		<parent link="link4a"/>
		<child link="link4b"/>
		<dynamics damping="0.7" friction="0.0"/>
	</joint>

	<transmission name="tran4">
		<type>transmission_interface/SimpleTransmission</type>
		<joint name="joint4">
			<hardwareInterface>EffortJointInterface</hardwareInterface>
		</joint>
		<actuator name="motor4">
			<mechanicalReduction>1</mechanicalReduction>
		</actuator>
	</transmission>

	<link name="link4b">
		<!--<collision>
			<origin xyz="0 0 0" rpy="0 0 0"/>
			<geometry>
				<mesh filename="package://hdt_mk3_m_description/meshes/hdt_mk3_m_4b.STL"/>
			</geometry>
		</collision>-->

		<visual>
			<origin xyz="0 0 0.0" rpy="0 0 0"/>
			<geometry>
				<mesh filename="package://hdt_mk3_m_description/meshes/hdt_mk3_m_4b.STL"/>
			</geometry>
			<material name="titanium"/>
		</visual>

		<!--<inertial>
			<origin xyz="0 -0.02018105 0" rpy="0 0 0"/>
			<mass value="0.69896279"/>
			<inertia
			ixx="0.00094182" ixy="0.0" ixz="0.0"
			iyy="0.00032992" iyz="0.0"
			izz="0.00088116"/>
		</inertial>-->
	</link>

	<!-- segment 5 -->
	<joint name="joint5" type="revolute">
		<hdt id="5"/>
		<axis xyz="0 -1 0"/>
		<limit effort="60.0" lower="-2.0944" upper="2.0944" velocity="2.0944"/>
		<origin xyz="-0.02573 -0.1062 -0.0420" rpy="0 0 0"/>
		<parent link="link4b"/>
		<child link="link5"/>
		<dynamics damping="0.7" friction="0.0"/>
	</joint>

	<transmission name="tran5">
		<type>transmission_interface/SimpleTransmission</type>
		<joint name="joint5">
			<hardwareInterface>EffortJointInterface</hardwareInterface>
		</joint>
		<actuator name="motor5">
			<mechanicalReduction>1</mechanicalReduction>
		</actuator>
	</transmission>

	<link name="link5">
		<!--<collision>
			<origin xyz="0 0 0.0" rpy="0 0 0"/>
			<geometry>
				<mesh filename="package://hdt_mk3_m_description/meshes/hdt_mk3_m_5.STL"/>
			</geometry>
		</collision>-->

		<visual>
			<origin xyz="0 0 0.0" rpy="0 0 0"/>
			<geometry>
				<mesh filename="package://hdt_mk3_m_description/meshes/hdt_mk3_m_5.STL"/>
			</geometry>
			<material name="yellow"/>
		</visual>

		<!--<inertial>
			<origin xyz="0 -0.04487724 0" rpy="0 0 0"/>
			<mass value="1.00775488"/>
			<inertia
			ixx="0.00104342" ixy="0.0" ixz="0.0"
			iyy="0.00064952" iyz="0.0"
			izz="0.00104342"/>
		</inertial>-->
	</link>

	<joint name="joint5f" type="fixed">
		<origin xyz="0 -0.08651 0" rpy="0 0 0"/>
		<parent link="link5"/>
		<child link="link6a"/>
	</joint>

	<link name="link6a">
		<!--<collision>
			<origin xyz="0 0 0" rpy="0 0 0"/>
			<geometry>
				<mesh filename="package://hdt_mk3_m_description/meshes/hdt_mk3_m_6a.STL"/>
			</geometry>
		</collision>-->

		<visual>
			<origin xyz="0 0 0.0" rpy="0 0 0"/>
			<geometry>
				<mesh filename="package://hdt_mk3_m_description/meshes/hdt_mk3_m_6a.STL"/>
			</geometry>
			<material name="titanium"/>
		</visual>

		<!--<inertial>
			<origin xyz="0 -0.04112 0" rpy="0 0 0"/>
			<mass value="0.50058"/>
			<inertia
			ixx="0.000580228" ixy="0.0" ixz="0.0"
			iyy="0.000541503" iyz="0.0"
			izz="0.000750977"/>
		</inertial>-->
	</link>

	<!-- segment 6 -->
	<joint name="joint6" type="revolute">
		<hdt id="6"/>
		<axis xyz="1 0 0"/>
		<limit effort="60.0" lower="-1.5708" upper="1.5708" velocity="2.0944"/>
		<origin xyz="0.02393 -0.0510 0" rpy="0 0 0"/>
		<parent link="link6a"/>
		<child link="link6b"/>
		<dynamics damping="0.7" friction="0.0"/>
	</joint>

	<transmission name="tran6">
		<type>transmission_interface/SimpleTransmission</type>
		<joint name="joint6">
			<hardwareInterface>EffortJointInterface</hardwareInterface>
		</joint>
		<actuator name="motor6">
			<mechanicalReduction>1</mechanicalReduction>
		</actuator>
	</transmission>

	<link name="link6b">
		<!--<collision>
			<origin xyz="0 0 0" rpy="0 0 0"/>
			<geometry>
				<mesh filename="package://hdt_mk3_m_description/meshes/hdt_mk3_m_6b.STL"/>
			</geometry>
		</collision>-->

		<visual>
			<origin xyz="0 0 0.0" rpy="0 0 0"/>
			<geometry>
				<mesh filename="package://hdt_mk3_m_description/meshes/hdt_mk3_m_6b.STL"/>
			</geometry>
			<material name="titanium"/>
		</visual>

		<!--<inertial>
			<origin xyz="0 -0.03855 0" rpy="0 0 0"/>
			<mass value="0.99934"/>
			<inertia
			ixx="0.001905243" ixy="0.0" ixz="0.0"
			iyy="0.000474765" iyz="0.0"
			izz="0.001905243"/>
		</inertial>-->
	</link>

	<!-- segment 7 -->
	<joint name="joint7" type="revolute">
		<hdt id="7"/>
		<axis xyz="0 0 1"/>
		<limit effort="60.0" lower="-1.5708" upper="1.5708" velocity="2.0944"/>
		<origin xyz="-0.02395 -0.08231 -0.02697" rpy="0 0 0"/>
		<parent link="link6b"/>
		<child link="link7"/>
		<dynamics damping="0.7" friction="0.0"/>
	</joint>

	<transmission name="tran7">
		<type>transmission_interface/SimpleTransmission</type>
		<joint name="joint7">
			<hardwareInterface>EffortJointInterface</hardwareInterface>
		</joint>
		<actuator name="motor7">
			<mechanicalReduction>1</mechanicalReduction>
		</actuator>
	</transmission>

	<link name="link7">
		<!--<collision>
			<origin xyz="0 0 0" rpy="0 0 0"/>
			<geometry>
				<mesh filename="package://hdt_mk3_m_description/meshes/hdt_mk3_m_7.STL"/>
			</geometry>
		</collision>-->

		<visual>
			<origin xyz="0 0 0.0" rpy="0 0 0"/>
			<geometry>
				<mesh filename="package://hdt_mk3_m_description/meshes/hdt_mk3_m_7.STL"/>
			</geometry>
			<material name="titanium"/>
		</visual>

		<!--<inertial>
			<origin xyz="0 -0.01177 0" rpy="0 0 0"/>
			<mass value="0.47608"/>
			<inertia
			ixx="0.000705091" ixy="0.0" ixz="0.0"
			iyy="0.000537081" iyz="0.0"
			izz="0.000534342"/>
		</inertial>-->
	</link>
</robot>

